Workbook

Sheet Sheet1
A1: Page | B1: Section | C1: Target Reviewer | D1: Action Taken (The "Why" and "How")
A2: 1 | B2: Abstract | C2: R1 (Pt 2, 5, 6) | D2: Integrated Unified Claims: Updated to include BPI 2017 validation. Balanced the 98% (synthetic) and 72.4% (real-world) savings to avoid overstating.
A3: 2 | B3: Introduction | C3: R1 (Pt 1) | D3: Novelty Reframing: Added the "Autonomous Logic-Adaptation Loop" paragraph. Switched focus from simple "integration" to an active agent that realigns discovery logic.
A4: 4 | B4: III-B: Parametric Model | C4: R1 (Pt 4) | D4: Notation Sync: Verified that math symbols ($\tau_{dep}$, $\tau_{loop}$, $\tau_{sig}$) match the column headers in the Results tables exactly.
A5: 5 | B5: III-F: Re-Optimization | C5: R1 (Pt 4) | D5: Methodological Defense: Added a 200-word justification for Grid Search. Cited exhaustive reproducibility in a finite 135-point space as a requirement for scientific validation.
A6: 12 | B6: IV-C: BPI 17 Setup | C6: R1 (Pt 2) / R2 | D6: NEW SUBSECTION (Data Profiling): Introduced BPI 2017 as a "Stress Test." Included Table 7 with Descriptive Stats (475k events) and explained the high-entropy nature of Variant A.
A7: 18 | B7: V-D: Practical Utility | C7: R1 (Pt 2, 7) / R2 | D7: NEW SUBSECTION (Results): Analyzed real-world behavior. Inserted Table 8 (Means) and Figures 8 & 9 (Trajectories and Drift Signals).
A8: 19 | B8: V-D.3: Sensitivity | C8: R1 (Pt 5, 7) | D8: Deep Insight Narrative: Explicitly addressed the 72.4% savings vs. 98% delta. Explained this as a result of "Stochastic Pulse" sensitivity versus "Episodic Drift" stability.
A9: 20 | B9: VI-B: Limitations | C9: R1 (Pt 7) | D9: NEW SUBSECTION: Provided a detailed academic discussion on threshold sensitivity ($\epsilon$) and the window size ($W$) trade-off between inertia and freshness.
A10: Global | B10: All Sections | C10: R1 (Pt 6) | D10: Tone & Conciseness: Deleted "heroic" adjectives (very, extremely, unique). Swapped absolute claims ("proves," "perfectly") for moderated ones ("demonstrates," "suggests").
A15: Feature | B15: S-BAR [7] | C15: Adaptive Windowing [8] | D15: Prefix-Tree Miners [18] | E15: Proposed Framework
A16: Ingestion | B16: Event Stream | C16: Event Stream | D16: Event Stream | E16: Event Stream
A17: Abstraction | B17: Aggregated DFGs | C17: Sliding Windows | D17: Prefix Trees | E17: Mini-Cubes (Isolated)
A18: Adaptation Target | B18: Graph Edge Counts | C18: Window/History Size | D18: Incremental Updates | E18: Logic ()
A19: Control Logic | B19: Passive | C19: Reactive | D19: Passive | E19: Autonomous / Strategy-Driven
A20: Drift Handling | B20: Continuous/Aging | C20: Threshold-based | D20: Incremental Growth | E20: Distributional (JSD)
A21: Multi-Objective | B21: No (Fixed) | C21: No (Fixed) | D21: No (Fixed) | E21: Yes (F, P, S)

Sheet ASSETS
V1: Metric | W1: New credit (Variant A) | X1: Limit raise (Variant B)
B2: Asset 1: Table 8 – Consolidated BPI17 Discovery Profile | V2: Events | W2: 429717 | X2: 45589
B3: Variant | C3: Strategy | D3: Mean Fitness | E3: Mean Precision | F3: Mean Structure | G3: Mean τdep | H3: Mean τloop | I3: Mean τsig | V3: Cases | W3: 28120 | X3: 3389
B4: New credit | C4: Fidelity | D4: =AVERAGEIFS('New credit'!J:J, 'New credit'!$D:$D, $C4) -> 0.71858327 | E4: =AVERAGEIFS('New credit'!K:K, 'New credit'!$D:$D, $C4) -> 0.77489698 | F4: =AVERAGEIFS('New credit'!L:L, 'New credit'!$D:$D, $C4) -> 0.64949198 | G4: =AVERAGEIFS('New credit'!G:G, 'New credit'!$D:$D, $C4) -> 0.1 | H4: =AVERAGEIFS('New credit'!H:H, 'New credit'!$D:$D, $C4) -> 0.4 | I4: =AVERAGEIFS('New credit'!I:I, 'New credit'!$D:$D, $C4) -> 0.05 | V4: Unique Traces | W4: 5356 | X4: 520
B5: New credit | C5: Strictness | D5: =AVERAGEIFS('New credit'!J:J, 'New credit'!$D:$D, $C5) -> 0.45843528 | E5: =AVERAGEIFS('New credit'!K:K, 'New credit'!$D:$D, $C5) -> 0.86196949 | F5: =AVERAGEIFS('New credit'!L:L, 'New credit'!$D:$D, $C5) -> 0.69893075 | G5: =AVERAGEIFS('New credit'!G:G, 'New credit'!$D:$D, $C5) -> 0.85920468 | H5: =AVERAGEIFS('New credit'!H:H, 'New credit'!$D:$D, $C5) -> 0.57305263 | I5: =AVERAGEIFS('New credit'!I:I, 'New credit'!$D:$D, $C5) -> 0.050982456 | V5: Avg. Trace Length | W5: 15.28 | X5: 13.45
B6: New credit | C6: Parsimony | D6: =AVERAGEIFS('New credit'!J:J, 'New credit'!$D:$D, $C6) -> 0.57264239 | E6: =AVERAGEIFS('New credit'!K:K, 'New credit'!$D:$D, $C6) -> 0.83770461 | F6: =AVERAGEIFS('New credit'!L:L, 'New credit'!$D:$D, $C6) -> 0.74240107 | G6: =AVERAGEIFS('New credit'!G:G, 'New credit'!$D:$D, $C6) -> 0.60844444 | H6: =AVERAGEIFS('New credit'!H:H, 'New credit'!$D:$D, $C6) -> 0.54568421 | I6: =AVERAGEIFS('New credit'!I:I, 'New credit'!$D:$D, $C6) -> 0.057719298 | V6: Density (Events/Case) | W6: 15.28 | X6: 13.45
B7: Limit raise | C7: Fidelity | D7: =AVERAGEIFS('Limit raise'!J:J, 'Limit raise'!$D:$D, $C7) -> 0.66660529 | E7: =AVERAGEIFS('Limit raise'!K:K, 'Limit raise'!$D:$D, $C7) -> 0.80454039 | F7: =AVERAGEIFS('Limit raise'!L:L, 'Limit raise'!$D:$D, $C7) -> 0.66650518 | G7: =AVERAGEIFS('Limit raise'!G:G, 'Limit raise'!$D:$D, $C7) -> 0.1 | H7: =AVERAGEIFS('Limit raise'!H:H, 'Limit raise'!$D:$D, $C7) -> 0.4 | I7: =AVERAGEIFS('Limit raise'!I:I, 'Limit raise'!$D:$D, $C7) -> 0.05
B8: Limit raise | C8: Strictness | D8: =AVERAGEIFS('Limit raise'!J:J, 'Limit raise'!$D:$D, $C8) -> 0.35849075 | E8: =AVERAGEIFS('Limit raise'!K:K, 'Limit raise'!$D:$D, $C8) -> 0.91644677 | F8: =AVERAGEIFS('Limit raise'!L:L, 'Limit raise'!$D:$D, $C8) -> 0.69221368 | G8: =AVERAGEIFS('Limit raise'!G:G, 'Limit raise'!$D:$D, $C8) -> 0.89887719 | H8: =AVERAGEIFS('Limit raise'!H:H, 'Limit raise'!$D:$D, $C8) -> 0.71452632 | I8: =AVERAGEIFS('Limit raise'!I:I, 'Limit raise'!$D:$D, $C8) -> 0.12663158
B9: Limit raise | C9: Parsimony | D9: =AVERAGEIFS('Limit raise'!J:J, 'Limit raise'!$D:$D, $C9) -> 0.50705219 | E9: =AVERAGEIFS('Limit raise'!K:K, 'Limit raise'!$D:$D, $C9) -> 0.89118569 | F9: =AVERAGEIFS('Limit raise'!L:L, 'Limit raise'!$D:$D, $C9) -> 0.81175472 | G9: =AVERAGEIFS('Limit raise'!G:G, 'Limit raise'!$D:$D, $C9) -> 0.73681871 | H9: =AVERAGEIFS('Limit raise'!H:H, 'Limit raise'!$D:$D, $C9) -> 0.65684211 | I9: =AVERAGEIFS('Limit raise'!I:I, 'Limit raise'!$D:$D, $C9) -> 0.050982456
B14: Asset 2: Figure 8 – Longitudinal Quality & Trigger Synchronization
O15: Figure 8 – Longitudinal Quality & Trigger Synchronization -
D16: Fidelity | E16: Strictness | F16: Parsimony | I16: Fidelity | J16: Strictness | K16: Parsimony
C17: ITERATION | D17: fitness_score | E17: precision_score | F17: structure_score | G17: drift_magnitude | H17: drift_threshold | I17: fitness_score | J17: precision_score | K17: structure_score | L17: drift_magnitude | M17: drift_threshold
D18: Fitness | E18: Precision | F18: Structure | G18: Drift magnitude | H18: Drift threshold | I18: Fitness | J18: Precision | K18: Structure | L18: Drift magnitude | M18: Drift threshold
C19: 1 | D19: {=INDEX('New credit'!$A:$O, MATCH(1,('New credit'!$A:$A=$C19)*('New credit'!$D:$D=D$16), 0), MATCH(D$17,'New credit'!$1:$1,0))} -> 0.79310345 | E19: {=INDEX('New credit'!$A:$O, MATCH(1,('New credit'!$A:$A=$C19)*('New credit'!$D:$D=E$16), 0), MATCH(E$17,'New credit'!$1:$1,0))} -> 0.89333333 | F19: {=INDEX('New credit'!$A:$O, MATCH(1,('New credit'!$A:$A=$C19)*('New credit'!$D:$D=F$16), 0), MATCH(F$17,'New credit'!$1:$1,0))} -> 0.6264863 | G19: =INDEX('New credit'!$A:$O, MATCH($C19, 'New credit'!$A:$A, 0), MATCH(G$17, 'New credit'!$1:$1, 0)) -> 1 | H19: 0.15 | I19: {=INDEX('Limit raise'!$A:$O, MATCH(1,('Limit raise'!$A:$A=$C19)*('Limit raise'!$D:$D=I$16), 0), MATCH(I$17,'Limit raise'!$1:$1,0))} -> 1 | J19: {=INDEX('Limit raise'!$A:$O, MATCH(1,('Limit raise'!$A:$A=$C19)*('Limit raise'!$D:$D=J$16), 0), MATCH(J$17,'Limit raise'!$1:$1,0))} -> 0.93142857 | K19: {=INDEX('Limit raise'!$A:$O, MATCH(1,('Limit raise'!$A:$A=$C19)*('Limit raise'!$D:$D=K$16), 0), MATCH(K$17,'Limit raise'!$1:$1,0))} -> 1 | L19: =INDEX('Limit raise'!$A:$O, MATCH($C19, 'Limit raise'!$A:$A, 0), MATCH(L$17,'Limit raise'!$1:$1,0)) -> 1 | M19: 0.15
C20: 2 | D20: {=INDEX('New credit'!$A:$O, MATCH(1,('New credit'!$A:$A=$C20)*('New credit'!$D:$D=D$16), 0), MATCH(D$17,'New credit'!$1:$1,0))} -> 0.83333333 | E20: {=INDEX('New credit'!$A:$O, MATCH(1,('New credit'!$A:$A=$C20)*('New credit'!$D:$D=E$16), 0), MATCH(E$17,'New credit'!$1:$1,0))} -> 0.90384615 | F20: {=INDEX('New credit'!$A:$O, MATCH(1,('New credit'!$A:$A=$C20)*('New credit'!$D:$D=F$16), 0), MATCH(F$17,'New credit'!$1:$1,0))} -> 0.6196678 | G20: =INDEX('New credit'!$A:$O, MATCH($C20, 'New credit'!$A:$A, 0), MATCH(G$17, 'New credit'!$1:$1, 0)) -> 0.075834592 | H20: 0.15 | I20: {=INDEX('Limit raise'!$A:$O, MATCH(1,('Limit raise'!$A:$A=$C20)*('Limit raise'!$D:$D=I$16), 0), MATCH(I$17,'Limit raise'!$1:$1,0))} -> 0.76923077 | J20: {=INDEX('Limit raise'!$A:$O, MATCH(1,('Limit raise'!$A:$A=$C20)*('Limit raise'!$D:$D=J$16), 0), MATCH(J$17,'Limit raise'!$1:$1,0))} -> 0.95714286 | K20: {=INDEX('Limit raise'!$A:$O, MATCH(1,('Limit raise'!$A:$A=$C20)*('Limit raise'!$D:$D=K$16), 0), MATCH(K$17,'Limit raise'!$1:$1,0))} -> 1 | L20: =INDEX('Limit raise'!$A:$O, MATCH($C20, 'Limit raise'!$A:$A, 0), MATCH(L$17,'Limit raise'!$1:$1,0)) -> 1 | M20: 0.15
C21: 3 | D21: {=INDEX('New credit'!$A:$O, MATCH(1,('New credit'!$A:$A=$C21)*('New credit'!$D:$D=D$16), 0), MATCH(D$17,'New credit'!$1:$1,0))} -> 0.78787879 | E21: {=INDEX('New credit'!$A:$O, MATCH(1,('New credit'!$A:$A=$C21)*('New credit'!$D:$D=E$16), 0), MATCH(E$17,'New credit'!$1:$1,0))} -> 0.91461538 | F21: {=INDEX('New credit'!$A:$O, MATCH(1,('New credit'!$A:$A=$C21)*('New credit'!$D:$D=F$16), 0), MATCH(F$17,'New credit'!$1:$1,0))} -> 0.67339138 | G21: =INDEX('New credit'!$A:$O, MATCH($C21, 'New credit'!$A:$A, 0), MATCH(G$17, 'New credit'!$1:$1, 0)) -> 1 | H21: 0.15 | I21: {=INDEX('Limit raise'!$A:$O, MATCH(1,('Limit raise'!$A:$A=$C21)*('Limit raise'!$D:$D=I$16), 0), MATCH(I$17,'Limit raise'!$1:$1,0))} -> 0.8 | J21: {=INDEX('Limit raise'!$A:$O, MATCH(1,('Limit raise'!$A:$A=$C21)*('Limit raise'!$D:$D=J$16), 0), MATCH(J$17,'Limit raise'!$1:$1,0))} -> 0.96375 | K21: {=INDEX('Limit raise'!$A:$O, MATCH(1,('Limit raise'!$A:$A=$C21)*('Limit raise'!$D:$D=K$16), 0), MATCH(K$17,'Limit raise'!$1:$1,0))} -> 0.35714286 | L21: =INDEX('Limit raise'!$A:$O, MATCH($C21, 'Limit raise'!$A:$A, 0), MATCH(L$17,'Limit raise'!$1:$1,0)) -> 0.072796843 | M21: 0.15
C22: 4 | D22: {=INDEX('New credit'!$A:$O, MATCH(1,('New credit'!$A:$A=$C22)*('New credit'!$D:$D=D$16), 0), MATCH(D$17,'New credit'!$1:$1,0))} -> 0.74358974 | E22: {=INDEX('New credit'!$A:$O, MATCH(1,('New credit'!$A:$A=$C22)*('New credit'!$D:$D=E$16), 0), MATCH(E$17,'New credit'!$1:$1,0))} -> 0.91384615 | F22: {=INDEX('New credit'!$A:$O, MATCH(1,('New credit'!$A:$A=$C22)*('New credit'!$D:$D=F$16), 0), MATCH(F$17,'New credit'!$1:$1,0))} -> 0.75632295 | G22: =INDEX('New credit'!$A:$O, MATCH($C22, 'New credit'!$A:$A, 0), MATCH(G$17, 'New credit'!$1:$1, 0)) -> 1 | H22: 0.15 | I22: {=INDEX('Limit raise'!$A:$O, MATCH(1,('Limit raise'!$A:$A=$C22)*('Limit raise'!$D:$D=I$16), 0), MATCH(I$17,'Limit raise'!$1:$1,0))} -> 0.84615385 | J22: {=INDEX('Limit raise'!$A:$O, MATCH(1,('Limit raise'!$A:$A=$C22)*('Limit raise'!$D:$D=J$16), 0), MATCH(J$17,'Limit raise'!$1:$1,0))} -> 0.97375 | K22: {=INDEX('Limit raise'!$A:$O, MATCH(1,('Limit raise'!$A:$A=$C22)*('Limit raise'!$D:$D=K$16), 0), MATCH(K$17,'Limit raise'!$1:$1,0))} -> 0.83189655 | L22: =INDEX('Limit raise'!$A:$O, MATCH($C22, 'Limit raise'!$A:$A, 0), MATCH(L$17,'Limit raise'!$1:$1,0)) -> 1 | M22: 0.15
C23: 5 | D23: {=INDEX('New credit'!$A:$O, MATCH(1,('New credit'!$A:$A=$C23)*('New credit'!$D:$D=D$16), 0), MATCH(D$17,'New credit'!$1:$1,0))} -> 0.78 | E23: {=INDEX('New credit'!$A:$O, MATCH(1,('New credit'!$A:$A=$C23)*('New credit'!$D:$D=E$16), 0), MATCH(E$17,'New credit'!$1:$1,0))} -> 0.91153846 | F23: {=INDEX('New credit'!$A:$O, MATCH(1,('New credit'!$A:$A=$C23)*('New credit'!$D:$D=F$16), 0), MATCH(F$17,'New credit'!$1:$1,0))} -> 0.83007178 | G23: =INDEX('New credit'!$A:$O, MATCH($C23, 'New credit'!$A:$A, 0), MATCH(G$17, 'New credit'!$1:$1, 0)) -> 1 | H23: 0.15 | I23: {=INDEX('Limit raise'!$A:$O, MATCH(1,('Limit raise'!$A:$A=$C23)*('Limit raise'!$D:$D=I$16), 0), MATCH(I$17,'Limit raise'!$1:$1,0))} -> 0.85714286 | J23: {=INDEX('Limit raise'!$A:$O, MATCH(1,('Limit raise'!$A:$A=$C23)*('Limit raise'!$D:$D=J$16), 0), MATCH(J$17,'Limit raise'!$1:$1,0))} -> 0.98 | K23: {=INDEX('Limit raise'!$A:$O, MATCH(1,('Limit raise'!$A:$A=$C23)*('Limit raise'!$D:$D=K$16), 0), MATCH(K$17,'Limit raise'!$1:$1,0))} -> 0.66478873 | L23: =INDEX('Limit raise'!$A:$O, MATCH($C23, 'Limit raise'!$A:$A, 0), MATCH(L$17,'Limit raise'!$1:$1,0)) -> 1 | M23: 0.15
C24: 6 | D24: {=INDEX('New credit'!$A:$O, MATCH(1,('New credit'!$A:$A=$C24)*('New credit'!$D:$D=D$16), 0), MATCH(D$17,'New credit'!$1:$1,0))} -> 0.76363636 | E24: {=INDEX('New credit'!$A:$O, MATCH(1,('New credit'!$A:$A=$C24)*('New credit'!$D:$D=E$16), 0), MATCH(E$17,'New credit'!$1:$1,0))} -> 0.910625 | F24: {=INDEX('New credit'!$A:$O, MATCH(1,('New credit'!$A:$A=$C24)*('New credit'!$D:$D=F$16), 0), MATCH(F$17,'New credit'!$1:$1,0))} -> 0.79701592 | G24: =INDEX('New credit'!$A:$O, MATCH($C24, 'New credit'!$A:$A, 0), MATCH(G$17, 'New credit'!$1:$1, 0)) -> 0.083866456 | H24: 0.15 | I24: {=INDEX('Limit raise'!$A:$O, MATCH(1,('Limit raise'!$A:$A=$C24)*('Limit raise'!$D:$D=I$16), 0), MATCH(I$17,'Limit raise'!$1:$1,0))} -> 0.875 | J24: {=INDEX('Limit raise'!$A:$O, MATCH(1,('Limit raise'!$A:$A=$C24)*('Limit raise'!$D:$D=J$16), 0), MATCH(J$17,'Limit raise'!$1:$1,0))} -> 0.97 | K24: {=INDEX('Limit raise'!$A:$O, MATCH(1,('Limit raise'!$A:$A=$C24)*('Limit raise'!$D:$D=K$16), 0), MATCH(K$17,'Limit raise'!$1:$1,0))} -> 0.76829268 | L24: =INDEX('Limit raise'!$A:$O, MATCH($C24, 'Limit raise'!$A:$A, 0), MATCH(L$17,'Limit raise'!$1:$1,0)) -> 1 | M24: 0.15
C25: 7 | D25: {=INDEX('New credit'!$A:$O, MATCH(1,('New credit'!$A:$A=$C25)*('New credit'!$D:$D=D$16), 0), MATCH(D$17,'New credit'!$1:$1,0))} -> 0.73770492 | E25: {=INDEX('New credit'!$A:$O, MATCH(1,('New credit'!$A:$A=$C25)*('New credit'!$D:$D=E$16), 0), MATCH(E$17,'New credit'!$1:$1,0))} -> 0.91619048 | F25: {=INDEX('New credit'!$A:$O, MATCH(1,('New credit'!$A:$A=$C25)*('New credit'!$D:$D=F$16), 0), MATCH(F$17,'New credit'!$1:$1,0))} -> 0.79961604 | G25: =INDEX('New credit'!$A:$O, MATCH($C25, 'New credit'!$A:$A, 0), MATCH(G$17, 'New credit'!$1:$1, 0)) -> 1 | H25: 0.15 | I25: {=INDEX('Limit raise'!$A:$O, MATCH(1,('Limit raise'!$A:$A=$C25)*('Limit raise'!$D:$D=I$16), 0), MATCH(I$17,'Limit raise'!$1:$1,0))} -> 0.87878788 | J25: {=INDEX('Limit raise'!$A:$O, MATCH(1,('Limit raise'!$A:$A=$C25)*('Limit raise'!$D:$D=J$16), 0), MATCH(J$17,'Limit raise'!$1:$1,0))} -> 0.88769231 | K25: {=INDEX('Limit raise'!$A:$O, MATCH(1,('Limit raise'!$A:$A=$C25)*('Limit raise'!$D:$D=K$16), 0), MATCH(K$17,'Limit raise'!$1:$1,0))} -> 0.65091185 | L25: =INDEX('Limit raise'!$A:$O, MATCH($C25, 'Limit raise'!$A:$A, 0), MATCH(L$17,'Limit raise'!$1:$1,0)) -> 0.052925159 | M25: 0.15
C26: 8 | D26: {=INDEX('New credit'!$A:$O, MATCH(1,('New credit'!$A:$A=$C26)*('New credit'!$D:$D=D$16), 0), MATCH(D$17,'New credit'!$1:$1,0))} -> 0.78947368 | E26: {=INDEX('New credit'!$A:$O, MATCH(1,('New credit'!$A:$A=$C26)*('New credit'!$D:$D=E$16), 0), MATCH(E$17,'New credit'!$1:$1,0))} -> 0.80833333 | F26: {=INDEX('New credit'!$A:$O, MATCH(1,('New credit'!$A:$A=$C26)*('New credit'!$D:$D=F$16), 0), MATCH(F$17,'New credit'!$1:$1,0))} -> 0.70023615 | G26: =INDEX('New credit'!$A:$O, MATCH($C26, 'New credit'!$A:$A, 0), MATCH(G$17, 'New credit'!$1:$1, 0)) -> 0.093758864 | H26: 0.15 | I26: {=INDEX('Limit raise'!$A:$O, MATCH(1,('Limit raise'!$A:$A=$C26)*('Limit raise'!$D:$D=I$16), 0), MATCH(I$17,'Limit raise'!$1:$1,0))} -> 0.83333333 | J26: {=INDEX('Limit raise'!$A:$O, MATCH(1,('Limit raise'!$A:$A=$C26)*('Limit raise'!$D:$D=J$16), 0), MATCH(J$17,'Limit raise'!$1:$1,0))} -> 0.89615385 | K26: {=INDEX('Limit raise'!$A:$O, MATCH(1,('Limit raise'!$A:$A=$C26)*('Limit raise'!$D:$D=K$16), 0), MATCH(K$17,'Limit raise'!$1:$1,0))} -> 0.69512992 | L26: =INDEX('Limit raise'!$A:$O, MATCH($C26, 'Limit raise'!$A:$A, 0), MATCH(L$17,'Limit raise'!$1:$1,0)) -> 0.091936521 | M26: 0.15
C27: 9 | D27: {=INDEX('New credit'!$A:$O, MATCH(1,('New credit'!$A:$A=$C27)*('New credit'!$D:$D=D$16), 0), MATCH(D$17,'New credit'!$1:$1,0))} -> 0.80357143 | E27: {=INDEX('New credit'!$A:$O, MATCH(1,('New credit'!$A:$A=$C27)*('New credit'!$D:$D=E$16), 0), MATCH(E$17,'New credit'!$1:$1,0))} -> 0.85769231 | F27: {=INDEX('New credit'!$A:$O, MATCH(1,('New credit'!$A:$A=$C27)*('New credit'!$D:$D=F$16), 0), MATCH(F$17,'New credit'!$1:$1,0))} -> 0.76026256 | G27: =INDEX('New credit'!$A:$O, MATCH($C27, 'New credit'!$A:$A, 0), MATCH(G$17, 'New credit'!$1:$1, 0)) -> 0.17484676 | H27: 0.15 | I27: {=INDEX('Limit raise'!$A:$O, MATCH(1,('Limit raise'!$A:$A=$C27)*('Limit raise'!$D:$D=I$16), 0), MATCH(I$17,'Limit raise'!$1:$1,0))} -> 0.8 | J27: {=INDEX('Limit raise'!$A:$O, MATCH(1,('Limit raise'!$A:$A=$C27)*('Limit raise'!$D:$D=J$16), 0), MATCH(J$17,'Limit raise'!$1:$1,0))} -> 0.84266667 | K27: {=INDEX('Limit raise'!$A:$O, MATCH(1,('Limit raise'!$A:$A=$C27)*('Limit raise'!$D:$D=K$16), 0), MATCH(K$17,'Limit raise'!$1:$1,0))} -> 0.51870256 | L27: =INDEX('Limit raise'!$A:$O, MATCH($C27, 'Limit raise'!$A:$A, 0), MATCH(L$17,'Limit raise'!$1:$1,0)) -> 0.13823651 | M27: 0.15
C28: 10 | D28: {=INDEX('New credit'!$A:$O, MATCH(1,('New credit'!$A:$A=$C28)*('New credit'!$D:$D=D$16), 0), MATCH(D$17,'New credit'!$1:$1,0))} -> 0.81818182 | E28: {=INDEX('New credit'!$A:$O, MATCH(1,('New credit'!$A:$A=$C28)*('New credit'!$D:$D=E$16), 0), MATCH(E$17,'New credit'!$1:$1,0))} -> 0.86241379 | F28: {=INDEX('New credit'!$A:$O, MATCH(1,('New credit'!$A:$A=$C28)*('New credit'!$D:$D=F$16), 0), MATCH(F$17,'New credit'!$1:$1,0))} -> 0.76494364 | G28: =INDEX('New credit'!$A:$O, MATCH($C28, 'New credit'!$A:$A, 0), MATCH(G$17, 'New credit'!$1:$1, 0)) -> 0.072918543 | H28: 0.15 | I28: {=INDEX('Limit raise'!$A:$O, MATCH(1,('Limit raise'!$A:$A=$C28)*('Limit raise'!$D:$D=I$16), 0), MATCH(I$17,'Limit raise'!$1:$1,0))} -> 0.8 | J28: {=INDEX('Limit raise'!$A:$O, MATCH(1,('Limit raise'!$A:$A=$C28)*('Limit raise'!$D:$D=J$16), 0), MATCH(J$17,'Limit raise'!$1:$1,0))} -> 0.97142857 | K28: {=INDEX('Limit raise'!$A:$O, MATCH(1,('Limit raise'!$A:$A=$C28)*('Limit raise'!$D:$D=K$16), 0), MATCH(K$17,'Limit raise'!$1:$1,0))} -> 0.71824685 | L28: =INDEX('Limit raise'!$A:$O, MATCH($C28, 'Limit raise'!$A:$A, 0), MATCH(L$17,'Limit raise'!$1:$1,0)) -> 1 | M28: 0.15
C29: 11 | D29: {=INDEX('New credit'!$A:$O, MATCH(1,('New credit'!$A:$A=$C29)*('New credit'!$D:$D=D$16), 0), MATCH(D$17,'New credit'!$1:$1,0))} -> 0.82142857 | E29: {=INDEX('New credit'!$A:$O, MATCH(1,('New credit'!$A:$A=$C29)*('New credit'!$D:$D=E$16), 0), MATCH(E$17,'New credit'!$1:$1,0))} -> 0.86517241 | F29: {=INDEX('New credit'!$A:$O, MATCH(1,('New credit'!$A:$A=$C29)*('New credit'!$D:$D=F$16), 0), MATCH(F$17,'New credit'!$1:$1,0))} -> 0.64914905 | G29: =INDEX('New credit'!$A:$O, MATCH($C29, 'New credit'!$A:$A, 0), MATCH(G$17, 'New credit'!$1:$1, 0)) -> 0.11230528 | H29: 0.15 | I29: {=INDEX('Limit raise'!$A:$O, MATCH(1,('Limit raise'!$A:$A=$C29)*('Limit raise'!$D:$D=I$16), 0), MATCH(I$17,'Limit raise'!$1:$1,0))} -> 0.77777778 | J29: {=INDEX('Limit raise'!$A:$O, MATCH(1,('Limit raise'!$A:$A=$C29)*('Limit raise'!$D:$D=J$16), 0), MATCH(J$17,'Limit raise'!$1:$1,0))} -> 0.965625 | K29: {=INDEX('Limit raise'!$A:$O, MATCH(1,('Limit raise'!$A:$A=$C29)*('Limit raise'!$D:$D=K$16), 0), MATCH(K$17,'Limit raise'!$1:$1,0))} -> 0.67243844 | L29: =INDEX('Limit raise'!$A:$O, MATCH($C29, 'Limit raise'!$A:$A, 0), MATCH(L$17,'Limit raise'!$1:$1,0)) -> 0.03357926 | M29: 0.15
C30: 12 | D30: {=INDEX('New credit'!$A:$O, MATCH(1,('New credit'!$A:$A=$C30)*('New credit'!$D:$D=D$16), 0), MATCH(D$17,'New credit'!$1:$1,0))} -> 0.79245283 | E30: {=INDEX('New credit'!$A:$O, MATCH(1,('New credit'!$A:$A=$C30)*('New credit'!$D:$D=E$16), 0), MATCH(E$17,'New credit'!$1:$1,0))} -> 0.89296296 | F30: {=INDEX('New credit'!$A:$O, MATCH(1,('New credit'!$A:$A=$C30)*('New credit'!$D:$D=F$16), 0), MATCH(F$17,'New credit'!$1:$1,0))} -> 0.70483801 | G30: =INDEX('New credit'!$A:$O, MATCH($C30, 'New credit'!$A:$A, 0), MATCH(G$17, 'New credit'!$1:$1, 0)) -> 1 | H30: 0.15 | I30: {=INDEX('Limit raise'!$A:$O, MATCH(1,('Limit raise'!$A:$A=$C30)*('Limit raise'!$D:$D=I$16), 0), MATCH(I$17,'Limit raise'!$1:$1,0))} -> 0.80851064 | J30: {=INDEX('Limit raise'!$A:$O, MATCH(1,('Limit raise'!$A:$A=$C30)*('Limit raise'!$D:$D=J$16), 0), MATCH(J$17,'Limit raise'!$1:$1,0))} -> 0.97133333 | K30: {=INDEX('Limit raise'!$A:$O, MATCH(1,('Limit raise'!$A:$A=$C30)*('Limit raise'!$D:$D=K$16), 0), MATCH(K$17,'Limit raise'!$1:$1,0))} -> 0.68330151 | L30: =INDEX('Limit raise'!$A:$O, MATCH($C30, 'Limit raise'!$A:$A, 0), MATCH(L$17,'Limit raise'!$1:$1,0)) -> 0.053835211 | M30: 0.15
... C66: 48 | D66: {=INDEX('New credit'!$A:$O, MATCH(1,('New credit'!$A:$A=$C66)*('New credit'!$D:$D=D$16), 0), MATCH(D$17,'New credit'!$1:$1,0))} -> 0.65671642 | E66: {=INDEX('New credit'!$A:$O, MATCH(1,('New credit'!$A:$A=$C66)*('New credit'!$D:$D=E$16), 0), MATCH(E$17,'New credit'!$1:$1,0))} -> 0.86269231 | F66: {=INDEX('New credit'!$A:$O, MATCH(1,('New credit'!$A:$A=$C66)*('New credit'!$D:$D=F$16), 0), MATCH(F$17,'New credit'!$1:$1,0))} -> 0.78408191 | G66: =INDEX('New credit'!$A:$O, MATCH($C66, 'New credit'!$A:$A, 0), MATCH(G$17, 'New credit'!$1:$1, 0)) -> 0.084886182 | H66: 0.15 | I66: {=INDEX('Limit raise'!$A:$O, MATCH(1,('Limit raise'!$A:$A=$C66)*('Limit raise'!$D:$D=I$16), 0), MATCH(I$17,'Limit raise'!$1:$1,0))} -> 0.66153846 | J66: {=INDEX('Limit raise'!$A:$O, MATCH(1,('Limit raise'!$A:$A=$C66)*('Limit raise'!$D:$D=J$16), 0), MATCH(J$17,'Limit raise'!$1:$1,0))} -> 0.89222222 | K66: {=INDEX('Limit raise'!$A:$O, MATCH(1,('Limit raise'!$A:$A=$C66)*('Limit raise'!$D:$D=K$16), 0), MATCH(K$17,'Limit raise'!$1:$1,0))} -> 0.80145173 | L66: =INDEX('Limit raise'!$A:$O, MATCH($C66, 'Limit raise'!$A:$A, 0), MATCH(L$17,'Limit raise'!$1:$1,0)) -> 0.072833771 | M66: 0.15
C67: 49 | D67: {=INDEX('New credit'!$A:$O, MATCH(1,('New credit'!$A:$A=$C67)*('New credit'!$D:$D=D$16), 0), MATCH(D$17,'New credit'!$1:$1,0))} -> 0.734375 | E67: {=INDEX('New credit'!$A:$O, MATCH(1,('New credit'!$A:$A=$C67)*('New credit'!$D:$D=E$16), 0), MATCH(E$17,'New credit'!$1:$1,0))} -> 0.84033333 | F67: {=INDEX('New credit'!$A:$O, MATCH(1,('New credit'!$A:$A=$C67)*('New credit'!$D:$D=F$16), 0), MATCH(F$17,'New credit'!$1:$1,0))} -> 0.64296162 | G67: =INDEX('New credit'!$A:$O, MATCH($C67, 'New credit'!$A:$A, 0), MATCH(G$17, 'New credit'!$1:$1, 0)) -> 0.11241111 | H67: 0.15 | I67: {=INDEX('Limit raise'!$A:$O, MATCH(1,('Limit raise'!$A:$A=$C67)*('Limit raise'!$D:$D=I$16), 0), MATCH(I$17,'Limit raise'!$1:$1,0))} -> 0.64615385 | J67: {=INDEX('Limit raise'!$A:$O, MATCH(1,('Limit raise'!$A:$A=$C67)*('Limit raise'!$D:$D=J$16), 0), MATCH(J$17,'Limit raise'!$1:$1,0))} -> 0.92653846 | K67: {=INDEX('Limit raise'!$A:$O, MATCH(1,('Limit raise'!$A:$A=$C67)*('Limit raise'!$D:$D=K$16), 0), MATCH(K$17,'Limit raise'!$1:$1,0))} -> 0.87292683 | L67: =INDEX('Limit raise'!$A:$O, MATCH($C67, 'Limit raise'!$A:$A, 0), MATCH(L$17,'Limit raise'!$1:$1,0)) -> 0.073233893 | M67: 0.15 | O67: Asset 3: Figure 9 – JSD Drift Signal (The "Sensitivity" Plot)
C68: 50 | D68: {=INDEX('New credit'!$A:$O, MATCH(1,('New credit'!$A:$A=$C68)*('New credit'!$D:$D=D$16), 0), MATCH(D$17,'New credit'!$1:$1,0))} -> 0.80645161 | E68: {=INDEX('New credit'!$A:$O, MATCH(1,('New credit'!$A:$A=$C68)*('New credit'!$D:$D=E$16), 0), MATCH(E$17,'New credit'!$1:$1,0))} -> 0.86666667 | F68: {=INDEX('New credit'!$A:$O, MATCH(1,('New credit'!$A:$A=$C68)*('New credit'!$D:$D=F$16), 0), MATCH(F$17,'New credit'!$1:$1,0))} -> 0.77106754 | G68: =INDEX('New credit'!$A:$O, MATCH($C68, 'New credit'!$A:$A, 0), MATCH(G$17, 'New credit'!$1:$1, 0)) -> 0.16016058 | H68: 0.15 | I68: {=INDEX('Limit raise'!$A:$O, MATCH(1,('Limit raise'!$A:$A=$C68)*('Limit raise'!$D:$D=I$16), 0), MATCH(I$17,'Limit raise'!$1:$1,0))} -> 0.64615385 | J68: {=INDEX('Limit raise'!$A:$O, MATCH(1,('Limit raise'!$A:$A=$C68)*('Limit raise'!$D:$D=J$16), 0), MATCH(J$17,'Limit raise'!$1:$1,0))} -> 0.92615385 | K68: {=INDEX('Limit raise'!$A:$O, MATCH(1,('Limit raise'!$A:$A=$C68)*('Limit raise'!$D:$D=K$16), 0), MATCH(K$17,'Limit raise'!$1:$1,0))} -> 0.8738478 | L68: =INDEX('Limit raise'!$A:$O, MATCH($C68, 'Limit raise'!$A:$A, 0), MATCH(L$17,'Limit raise'!$1:$1,0)) -> 0.073812174 | M68: 0.15
C69: 51 | D69: {=INDEX('New credit'!$A:$O, MATCH(1,('New credit'!$A:$A=$C69)*('New credit'!$D:$D=D$16), 0), MATCH(D$17,'New credit'!$1:$1,0))} -> 0.74603175 | E69: {=INDEX('New credit'!$A:$O, MATCH(1,('New credit'!$A:$A=$C69)*('New credit'!$D:$D=E$16), 0), MATCH(E$17,'New credit'!$1:$1,0))} -> 0.83482759 | F69: {=INDEX('New credit'!$A:$O, MATCH(1,('New credit'!$A:$A=$C69)*('New credit'!$D:$D=F$16), 0), MATCH(F$17,'New credit'!$1:$1,0))} -> 0.77165231 | G69: =INDEX('New credit'!$A:$O, MATCH($C69, 'New credit'!$A:$A, 0), MATCH(G$17, 'New credit'!$1:$1, 0)) -> 0.14230698 | H69: 0.15 | I69: {=INDEX('Limit raise'!$A:$O, MATCH(1,('Limit raise'!$A:$A=$C69)*('Limit raise'!$D:$D=I$16), 0), MATCH(I$17,'Limit raise'!$1:$1,0))} -> 0.61538462 | J69: {=INDEX('Limit raise'!$A:$O, MATCH(1,('Limit raise'!$A:$A=$C69)*('Limit raise'!$D:$D=J$16), 0), MATCH(J$17,'Limit raise'!$1:$1,0))} -> 0.8888 | K69: {=INDEX('Limit raise'!$A:$O, MATCH(1,('Limit raise'!$A:$A=$C69)*('Limit raise'!$D:$D=K$16), 0), MATCH(K$17,'Limit raise'!$1:$1,0))} -> 0.78802163 | L69: =INDEX('Limit raise'!$A:$O, MATCH($C69, 'Limit raise'!$A:$A, 0), MATCH(L$17,'Limit raise'!$1:$1,0)) -> 0.072324588 | M69: 0.15
C70: 52 | D70: {=INDEX('New credit'!$A:$O, MATCH(1,('New credit'!$A:$A=$C70)*('New credit'!$D:$D=D$16), 0), MATCH(D$17,'New credit'!$1:$1,0))} -> 0.77192982 | E70: {=INDEX('New credit'!$A:$O, MATCH(1,('New credit'!$A:$A=$C70)*('New credit'!$D:$D=E$16), 0), MATCH(E$17,'New credit'!$1:$1,0))} -> 0.8892 | F70: {=INDEX('New credit'!$A:$O, MATCH(1,('New credit'!$A:$A=$C70)*('New credit'!$D:$D=F$16), 0), MATCH(F$17,'New credit'!$1:$1,0))} -> 0.80881833 | G70: =INDEX('New credit'!$A:$O, MATCH($C70, 'New credit'!$A:$A, 0), MATCH(G$17, 'New credit'!$1:$1, 0)) -> 1 | H70: 0.15 | I70: {=INDEX('Limit raise'!$A:$O, MATCH(1,('Limit raise'!$A:$A=$C70)*('Limit raise'!$D:$D=I$16), 0), MATCH(I$17,'Limit raise'!$1:$1,0))} -> 0.58461538 | J70: {=INDEX('Limit raise'!$A:$O, MATCH(1,('Limit raise'!$A:$A=$C70)*('Limit raise'!$D:$D=J$16), 0), MATCH(J$17,'Limit raise'!$1:$1,0))} -> 0.88695652 | K70: {=INDEX('Limit raise'!$A:$O, MATCH(1,('Limit raise'!$A:$A=$C70)*('Limit raise'!$D:$D=K$16), 0), MATCH(K$17,'Limit raise'!$1:$1,0))} -> 0.77763163 | L70: =INDEX('Limit raise'!$A:$O, MATCH($C70, 'Limit raise'!$A:$A, 0), MATCH(L$17,'Limit raise'!$1:$1,0)) -> 0.071249426 | M70: 0.15
C71: 53 | D71: {=INDEX('New credit'!$A:$O, MATCH(1,('New credit'!$A:$A=$C71)*('New credit'!$D:$D=D$16), 0), MATCH(D$17,'New credit'!$1:$1,0))} -> 0.74509804 | E71: {=INDEX('New credit'!$A:$O, MATCH(1,('New credit'!$A:$A=$C71)*('New credit'!$D:$D=E$16), 0), MATCH(E$17,'New credit'!$1:$1,0))} -> 0.86413793 | F71: {=INDEX('New credit'!$A:$O, MATCH(1,('New credit'!$A:$A=$C71)*('New credit'!$D:$D=F$16), 0), MATCH(F$17,'New credit'!$1:$1,0))} -> 0.75144122 | G71: =INDEX('New credit'!$A:$O, MATCH($C71, 'New credit'!$A:$A, 0), MATCH(G$17, 'New credit'!$1:$1, 0)) -> 0.11282732 | H71: 0.15 | I71: {=INDEX('Limit raise'!$A:$O, MATCH(1,('Limit raise'!$A:$A=$C71)*('Limit raise'!$D:$D=I$16), 0), MATCH(I$17,'Limit raise'!$1:$1,0))} -> 0.58461538 | J71: {=INDEX('Limit raise'!$A:$O, MATCH(1,('Limit raise'!$A:$A=$C71)*('Limit raise'!$D:$D=J$16), 0), MATCH(J$17,'Limit raise'!$1:$1,0))} -> 0.8873913 | K71: {=INDEX('Limit raise'!$A:$O, MATCH(1,('Limit raise'!$A:$A=$C71)*('Limit raise'!$D:$D=K$16), 0), MATCH(K$17,'Limit raise'!$1:$1,0))} -> 0.77814257 | L71: =INDEX('Limit raise'!$A:$O, MATCH($C71, 'Limit raise'!$A:$A, 0), MATCH(L$17,'Limit raise'!$1:$1,0)) -> 0.075482436 | M71: 0.15
C72: 54 | D72: {=INDEX('New credit'!$A:$O, MATCH(1,('New credit'!$A:$A=$C72)*('New credit'!$D:$D=D$16), 0), MATCH(D$17,'New credit'!$1:$1,0))} -> 0.73684211 | E72: {=INDEX('New credit'!$A:$O, MATCH(1,('New credit'!$A:$A=$C72)*('New credit'!$D:$D=E$16), 0), MATCH(E$17,'New credit'!$1:$1,0))} -> 0.86 | F72: {=INDEX('New credit'!$A:$O, MATCH(1,('New credit'!$A:$A=$C72)*('New credit'!$D:$D=F$16), 0), MATCH(F$17,'New credit'!$1:$1,0))} -> 0.70959715 | G72: =INDEX('New credit'!$A:$O, MATCH($C72, 'New credit'!$A:$A, 0), MATCH(G$17, 'New credit'!$1:$1, 0)) -> 1 | H72: 0.15 | I72: {=INDEX('Limit raise'!$A:$O, MATCH(1,('Limit raise'!$A:$A=$C72)*('Limit raise'!$D:$D=I$16), 0), MATCH(I$17,'Limit raise'!$1:$1,0))} -> 0.58461538 | J72: {=INDEX('Limit raise'!$A:$O, MATCH(1,('Limit raise'!$A:$A=$C72)*('Limit raise'!$D:$D=J$16), 0), MATCH(J$17,'Limit raise'!$1:$1,0))} -> 0.88782609 | K72: {=INDEX('Limit raise'!$A:$O, MATCH(1,('Limit raise'!$A:$A=$C72)*('Limit raise'!$D:$D=K$16), 0), MATCH(K$17,'Limit raise'!$1:$1,0))} -> 0.77936037 | L72: =INDEX('Limit raise'!$A:$O, MATCH($C72, 'Limit raise'!$A:$A, 0), MATCH(L$17,'Limit raise'!$1:$1,0)) -> 0.078129359 | M72: 0.15
C73: 55 | D73: {=INDEX('New credit'!$A:$O, MATCH(1,('New credit'!$A:$A=$C73)*('New credit'!$D:$D=D$16), 0), MATCH(D$17,'New credit'!$1:$1,0))} -> 0.78947368 | E73: {=INDEX('New credit'!$A:$O, MATCH(1,('New credit'!$A:$A=$C73)*('New credit'!$D:$D=E$16), 0), MATCH(E$17,'New credit'!$1:$1,0))} -> 0.85939394 | F73: {=INDEX('New credit'!$A:$O, MATCH(1,('New credit'!$A:$A=$C73)*('New credit'!$D:$D=F$16), 0), MATCH(F$17,'New credit'!$1:$1,0))} -> 0.66144174 | G73: =INDEX('New credit'!$A:$O, MATCH($C73, 'New credit'!$A:$A, 0), MATCH(G$17, 'New credit'!$1:$1, 0)) -> 0.08770948 | H73: 0.15 | I73: {=INDEX('Limit raise'!$A:$O, MATCH(1,('Limit raise'!$A:$A=$C73)*('Limit raise'!$D:$D=I$16), 0), MATCH(I$17,'Limit raise'!$1:$1,0))} -> 0.61538462 | J73: {=INDEX('Limit raise'!$A:$O, MATCH(1,('Limit raise'!$A:$A=$C73)*('Limit raise'!$D:$D=J$16), 0), MATCH(J$17,'Limit raise'!$1:$1,0))} -> 0.8896 | K73: {=INDEX('Limit raise'!$A:$O, MATCH(1,('Limit raise'!$A:$A=$C73)*('Limit raise'!$D:$D=K$16), 0), MATCH(K$17,'Limit raise'!$1:$1,0))} -> 0.79848635 | L73: =INDEX('Limit raise'!$A:$O, MATCH($C73, 'Limit raise'!$A:$A, 0), MATCH(L$17,'Limit raise'!$1:$1,0)) -> 0.077484809 | M73: 0.15
C74: 56 | D74: {=INDEX('New credit'!$A:$O, MATCH(1,('New credit'!$A:$A=$C74)*('New credit'!$D:$D=D$16), 0), MATCH(D$17,'New credit'!$1:$1,0))} -> 0.75438596 | E74: {=INDEX('New credit'!$A:$O, MATCH(1,('New credit'!$A:$A=$C74)*('New credit'!$D:$D=E$16), 0), MATCH(E$17,'New credit'!$1:$1,0))} -> 0.86424242 | F74: {=INDEX('New credit'!$A:$O, MATCH(1,('New credit'!$A:$A=$C74)*('New credit'!$D:$D=F$16), 0), MATCH(F$17,'New credit'!$1:$1,0))} -> 0.7209613 | G74: =INDEX('New credit'!$A:$O, MATCH($C74, 'New credit'!$A:$A, 0), MATCH(G$17, 'New credit'!$1:$1, 0)) -> 0.10844112 | H74: 0.15 | I74: {=INDEX('Limit raise'!$A:$O, MATCH(1,('Limit raise'!$A:$A=$C74)*('Limit raise'!$D:$D=I$16), 0), MATCH(I$17,'Limit raise'!$1:$1,0))} -> 0.63492063 | J74: {=INDEX('Limit raise'!$A:$O, MATCH(1,('Limit raise'!$A:$A=$C74)*('Limit raise'!$D:$D=J$16), 0), MATCH(J$17,'Limit raise'!$1:$1,0))} -> 0.8908 | K74: {=INDEX('Limit raise'!$A:$O, MATCH(1,('Limit raise'!$A:$A=$C74)*('Limit raise'!$D:$D=K$16), 0), MATCH(K$17,'Limit raise'!$1:$1,0))} -> 0.79928268 | L74: =INDEX('Limit raise'!$A:$O, MATCH($C74, 'Limit raise'!$A:$A, 0), MATCH(L$17,'Limit raise'!$1:$1,0)) -> 0.086256822 | M74: 0.15
C75: 57 | D75: {=INDEX('New credit'!$A:$O, MATCH(1,('New credit'!$A:$A=$C75)*('New credit'!$D:$D=D$16), 0), MATCH(D$17,'New credit'!$1:$1,0))} -> 0.75 | E75: {=INDEX('New credit'!$A:$O, MATCH(1,('New credit'!$A:$A=$C75)*('New credit'!$D:$D=E$16), 0), MATCH(E$17,'New credit'!$1:$1,0))} -> 0.87225806 | F75: {=INDEX('New credit'!$A:$O, MATCH(1,('New credit'!$A:$A=$C75)*('New credit'!$D:$D=F$16), 0), MATCH(F$17,'New credit'!$1:$1,0))} -> 0.66916116 | G75: =INDEX('New credit'!$A:$O, MATCH($C75, 'New credit'!$A:$A, 0), MATCH(G$17, 'New credit'!$1:$1, 0)) -> 0.17798392 | H75: 0.15 | I75: {=INDEX('Limit raise'!$A:$O, MATCH(1,('Limit raise'!$A:$A=$C75)*('Limit raise'!$D:$D=I$16), 0), MATCH(I$17,'Limit raise'!$1:$1,0))} -> 0.63492063 | J75: {=INDEX('Limit raise'!$A:$O, MATCH(1,('Limit raise'!$A:$A=$C75)*('Limit raise'!$D:$D=J$16), 0), MATCH(J$17,'Limit raise'!$1:$1,0))} -> 0.8908 | K75: {=INDEX('Limit raise'!$A:$O, MATCH(1,('Limit raise'!$A:$A=$C75)*('Limit raise'!$D:$D=K$16), 0), MATCH(K$17,'Limit raise'!$1:$1,0))} -> 0.80068257 | L75: =INDEX('Limit raise'!$A:$O, MATCH($C75, 'Limit raise'!$A:$A, 0), MATCH(L$17,'Limit raise'!$1:$1,0)) -> 0.088264429 | M75: 0.15
C76: 58 | D76: {=INDEX('New credit'!$A:$O, MATCH(1,('New credit'!$A:$A=$C76)*('New credit'!$D:$D=D$16), 0), MATCH(D$17,'New credit'!$1:$1,0))} -> 0.65079365 | E76: {=INDEX('New credit'!$A:$O, MATCH(1,('New credit'!$A:$A=$C76)*('New credit'!$D:$D=E$16), 0), MATCH(E$17,'New credit'!$1:$1,0))} -> 0.86517241 | F76: {=INDEX('New credit'!$A:$O, MATCH(1,('New credit'!$A:$A=$C76)*('New credit'!$D:$D=F$16), 0), MATCH(F$17,'New credit'!$1:$1,0))} -> 0.73172073 | G76: =INDEX('New credit'!$A:$O, MATCH($C76, 'New credit'!$A:$A, 0), MATCH(G$17, 'New credit'!$1:$1, 0)) -> 1 | H76: 0.15 | I76: {=INDEX('Limit raise'!$A:$O, MATCH(1,('Limit raise'!$A:$A=$C76)*('Limit raise'!$D:$D=I$16), 0), MATCH(I$17,'Limit raise'!$1:$1,0))} -> 0.609375 | J76: {=INDEX('Limit raise'!$A:$O, MATCH(1,('Limit raise'!$A:$A=$C76)*('Limit raise'!$D:$D=J$16), 0), MATCH(J$17,'Limit raise'!$1:$1,0))} -> 0.8908 | K76: {=INDEX('Limit raise'!$A:$O, MATCH(1,('Limit raise'!$A:$A=$C76)*('Limit raise'!$D:$D=K$16), 0), MATCH(K$17,'Limit raise'!$1:$1,0))} -> 0.80202488 | L76: =INDEX('Limit raise'!$A:$O, MATCH($C76, 'Limit raise'!$A:$A, 0), MATCH(L$17,'Limit raise'!$1:$1,0)) -> 0.090608237 | M76: 0.15
C77: 59 | D77: {=INDEX('New credit'!$A:$O, MATCH(1,('New credit'!$A:$A=$C77)*('New credit'!$D:$D=D$16), 0), MATCH(D$17,'New credit'!$1:$1,0))} -> 0.62711864 | E77: {=INDEX('New credit'!$A:$O, MATCH(1,('New credit'!$A:$A=$C77)*('New credit'!$D:$D=E$16), 0), MATCH(E$17,'New credit'!$1:$1,0))} -> 0.88583333 | F77: {=INDEX('New credit'!$A:$O, MATCH(1,('New credit'!$A:$A=$C77)*('New credit'!$D:$D=F$16), 0), MATCH(F$17,'New credit'!$1:$1,0))} -> 0.77081859 | G77: =INDEX('New credit'!$A:$O, MATCH($C77, 'New credit'!$A:$A, 0), MATCH(G$17, 'New credit'!$1:$1, 0)) -> 1 | H77: 0.15 | I77: {=INDEX('Limit raise'!$A:$O, MATCH(1,('Limit raise'!$A:$A=$C77)*('Limit raise'!$D:$D=I$16), 0), MATCH(I$17,'Limit raise'!$1:$1,0))} -> 0.609375 | J77: {=INDEX('Limit raise'!$A:$O, MATCH(1,('Limit raise'!$A:$A=$C77)*('Limit raise'!$D:$D=J$16), 0), MATCH(J$17,'Limit raise'!$1:$1,0))} -> 0.8916 | K77: {=INDEX('Limit raise'!$A:$O, MATCH(1,('Limit raise'!$A:$A=$C77)*('Limit raise'!$D:$D=K$16), 0), MATCH(K$17,'Limit raise'!$1:$1,0))} -> 0.80244466 | L77: =INDEX('Limit raise'!$A:$O, MATCH($C77, 'Limit raise'!$A:$A, 0), MATCH(L$17,'Limit raise'!$1:$1,0)) -> 0.09363703 | M77: 0.15
C78: 60 | D78: {=INDEX('New credit'!$A:$O, MATCH(1,('New credit'!$A:$A=$C78)*('New credit'!$D:$D=D$16), 0), MATCH(D$17,'New credit'!$1:$1,0))} -> 0.69090909 | E78: {=INDEX('New credit'!$A:$O, MATCH(1,('New credit'!$A:$A=$C78)*('New credit'!$D:$D=E$16), 0), MATCH(E$17,'New credit'!$1:$1,0))} -> 0.8528 | F78: {=INDEX('New credit'!$A:$O, MATCH(1,('New credit'!$A:$A=$C78)*('New credit'!$D:$D=F$16), 0), MATCH(F$17,'New credit'!$1:$1,0))} -> 0.733876 | G78: =INDEX('New credit'!$A:$O, MATCH($C78, 'New credit'!$A:$A, 0), MATCH(G$17, 'New credit'!$1:$1, 0)) -> 0.13761497 | H78: 0.15 | I78: {=INDEX('Limit raise'!$A:$O, MATCH(1,('Limit raise'!$A:$A=$C78)*('Limit raise'!$D:$D=I$16), 0), MATCH(I$17,'Limit raise'!$1:$1,0))} -> 0.625 | J78: {=INDEX('Limit raise'!$A:$O, MATCH(1,('Limit raise'!$A:$A=$C78)*('Limit raise'!$D:$D=J$16), 0), MATCH(J$17,'Limit raise'!$1:$1,0))} -> 0.89230769 | K78: {=INDEX('Limit raise'!$A:$O, MATCH(1,('Limit raise'!$A:$A=$C78)*('Limit raise'!$D:$D=K$16), 0), MATCH(K$17,'Limit raise'!$1:$1,0))} -> 0.82169696 | L78: =INDEX('Limit raise'!$A:$O, MATCH($C78, 'Limit raise'!$A:$A, 0), MATCH(L$17,'Limit raise'!$1:$1,0)) -> 0.091169685 | M78: 0.15
C79: 61 | D79: {=INDEX('New credit'!$A:$O, MATCH(1,('New credit'!$A:$A=$C79)*('New credit'!$D:$D=D$16), 0), MATCH(D$17,'New credit'!$1:$1,0))} -> 0.75 | E79: {=INDEX('New credit'!$A:$O, MATCH(1,('New credit'!$A:$A=$C79)*('New credit'!$D:$D=E$16), 0), MATCH(E$17,'New credit'!$1:$1,0))} -> 0.88333333 | F79: {=INDEX('New credit'!$A:$O, MATCH(1,('New credit'!$A:$A=$C79)*('New credit'!$D:$D=F$16), 0), MATCH(F$17,'New credit'!$1:$1,0))} -> 0.71957224 | G79: =INDEX('New credit'!$A:$O, MATCH($C79, 'New credit'!$A:$A, 0), MATCH(G$17, 'New credit'!$1:$1, 0)) -> 1 | H79: 0.15 | I79: {=INDEX('Limit raise'!$A:$O, MATCH(1,('Limit raise'!$A:$A=$C79)*('Limit raise'!$D:$D=I$16), 0), MATCH(I$17,'Limit raise'!$1:$1,0))} -> 0.640625 | J79: {=INDEX('Limit raise'!$A:$O, MATCH(1,('Limit raise'!$A:$A=$C79)*('Limit raise'!$D:$D=J$16), 0), MATCH(J$17,'Limit raise'!$1:$1,0))} -> 0.89148148 | K79: {=INDEX('Limit raise'!$A:$O, MATCH(1,('Limit raise'!$A:$A=$C79)*('Limit raise'!$D:$D=K$16), 0), MATCH(K$17,'Limit raise'!$1:$1,0))} -> 0.7977032 | L79: =INDEX('Limit raise'!$A:$O, MATCH($C79, 'Limit raise'!$A:$A, 0), MATCH(L$17,'Limit raise'!$1:$1,0)) -> 0.091141127 | M79: 0.15
...

Sheet ALL

Sheet Limit raise
A1: iteration | B1: cases_seen | C1: group | D1: strategy | E1: zone | F1: drift | G1: dep_threshold | H1: loop_threshold | I1: significance_threshold | J1: fitness_score | K1: precision_score | L1: structure_score | M1: criterion | N1: drift_magnitude | O1: triggered
A2: 1 | B2: 1000 | C2: Limit raise | D2: Fidelity | E2: Real-World | F2: N/A | G2: 0.1 | H2: 0.4 | I2: 0.05 | J2: 1 | K2: 0.915 | L2: 0.33333333 | M2: Optimized (JSD=1.000) | N2: 1 | O2: 1
A3: 2 | B3: 2000 | C3: Limit raise | D3: Fidelity | E3: Real-World | F3: N/A | G3: 0.1 | H3: 0.4 | I3: 0.05 | J3: 0.76923077 | K3: 0.876 | L3: 0.3 | M3: Optimized (JSD=1.000) | N3: 1 | O3: 1
A4: 3 | B4: 3000 | C4: Limit raise | D4: Fidelity | E4: Real-World | F4: N/A | G4: 0.1 | H4: 0.4 | I4: 0.05 | J4: 0.8 | K4: 0.83666667 | L4: 0.67857143 | M4: Skipped (JSD=0.073) | N4: 0.072796843 | O4: 0
A5: 4 | B5: 4000 | C5: Limit raise | D5: Fidelity | E5: Real-World | F5: N/A | G5: 0.1 | H5: 0.4 | I5: 0.05 | J5: 0.84615385 | K5: 0.71636364 | L5: 0.80957512 | M5: Optimized (JSD=1.000) | N5: 1 | O5: 1
A6: 5 | B6: 5000 | C6: Limit raise | D6: Fidelity | E6: Real-World | F6: N/A | G6: 0.1 | H6: 0.4 | I6: 0.05 | J6: 0.85714286 | K6: 0.73583333 | L6: 0.64534429 | M6: Optimized (JSD=1.000) | N6: 1 | O6: 1
A7: 6 | B7: 6000 | C7: Limit raise | D7: Fidelity | E7: Real-World | F7: N/A | G7: 0.1 | H7: 0.4 | I7: 0.05 | J7: 0.875 | K7: 0.73428571 | L7: 0.65448364 | M7: Optimized (JSD=1.000) | N7: 1 | O7: 1
A8: 7 | B8: 7000 | C8: Limit raise | D8: Fidelity | E8: Real-World | F8: N/A | G8: 0.1 | H8: 0.4 | I8: 0.05 | J8: 0.87878788 | K8: 0.7362069 | L8: 0.5896952 | M8: Skipped (JSD=0.053) | N8: 0.052925159 | O8: 0
A9: 8 | B9: 8000 | C9: Limit raise | D9: Fidelity | E9: Real-World | F9: N/A | G9: 0.1 | H9: 0.4 | I9: 0.05 | J9: 0.83333333 | K9: 0.75333333 | L9: 0.63616975 | M9: Skipped (JSD=0.092) | N9: 0.091936521 | O9: 0
A10: 9 | B10: 9000 | C10: Limit raise | D10: Fidelity | E10: Real-World | F10: N/A | G10: 0.1 | H10: 0.4 | I10: 0.05 | J10: 0.8 | K10: 0.769375 | L10: 0.64590618 | M10: Skipped (JSD=0.138) | N10: 0.13823651 | O10: 0
A11: 10 | B11: 10000 | C11: Limit raise | D11: Fidelity | E11: Real-World | F11: N/A | G11: 0.1 | H11: 0.4 | I11: 0.05 | J11: 0.8 | K11: 0.7425 | L11: 0.64659741 | M11: Optimized (JSD=1.000) | N11: 1 | O11: 1
A12: 11 | B12: 11000 | C12: Limit raise | D12: Fidelity | E12: Real-World | F12: N/A | G12: 0.1 | H12: 0.4 | I12: 0.05 | J12: 0.77777778 | K12: 0.76571429 | L12: 0.59599441 | M12: Skipped (JSD=0.034) | N12: 0.03357926 | O12: 0
A13: 12 | B13: 12000 | C13: Limit raise | D13: Fidelity | E13: Real-World | F13: N/A | G13: 0.1 | H13: 0.4 | I13: 0.05 | J13: 0.80851064 | K13: 0.74210526 | L13: 0.5761186 | M13: Skipped (JSD=0.054) | N13: 0.053835211 | O13: 0
... A1426: 475 | B1426: 475000 | C1426: Limit raise | D1426: Strictness | E1426: Real-World | F1426: N/A | G1426: 0.9 | H1426: 0.8 | I1426: 0.11666667 | J1426: 0.328125 | K1426: 0.93238095 | L1426: 0.81824602 | M1426: Skipped (JSD=0.121) | N1426: 0.12074718 | O1426: 0

Sheet New credit
A1: iteration | B1: cases_seen | C1: group | D1: strategy | E1: zone | F1: drift | G1: dep_threshold | H1: loop_threshold | I1: significance_threshold | J1: fitness_score | K1: precision_score | L1: structure_score | M1: criterion | N1: drift_magnitude | O1: triggered
A2: 1 | B2: 1000 | C2: New credit | D2: Fidelity | E2: Real-World | F2: N/A | G2: 0.1 | H2: 0.4 | I2: 0.05 | J2: 0.79310345 | K2: 0.7726087 | L2: 0.57312461 | M2: Optimized (JSD=1.000) | N2: 1 | O2: 1
A3: 1 | B3: 1000 | C3: New credit | D3: Parsimony | E3: Real-World | F3: N/A | G3: 0.1 | H3: 0.4 | I3: 0.18333333 | J3: 0.68965517 | K3: 0.768 | L3: 0.6264863 | M3: Optimized (JSD=1.000) | N3: 1 | O3: 1
A4: 1 | B4: 1000 | C4: New credit | D4: Strictness | E4: Real-World | F4: N/A | G4: 0.9 | H4: 0.4 | I4: 0.05 | J4: 0.4137931 | K4: 0.89333333 | L4: 0.45520768 | M4: Optimized (JSD=1.000) | N4: 1 | O4: 1
A5: 2 | B5: 2000 | C5: New credit | D5: Fidelity | E5: Real-World | F5: N/A | G5: 0.1 | H5: 0.4 | I5: 0.05 | J5: 0.83333333 | K5: 0.7616 | L5: 0.6789467 | M5: Skipped (JSD=0.076) | N5: 0.075834592 | O5: 0
A6: 2 | B6: 2000 | C6: New credit | D6: Parsimony | E6: Real-World | F6: N/A | G6: 0.1 | H6: 0.4 | I6: 0.18333333 | J6: 0.76666667 | K6: 0.75652174 | L6: 0.6196678 | M6: Skipped (JSD=0.076) | N6: 0.075834592 | O6: 0
A7: 2 | B7: 2000 | C7: New credit | D7: Strictness | E7: Real-World | F7: N/A | G7: 0.9 | H7: 0.4 | I7: 0.05 | J7: 0.43333333 | K7: 0.90384615 | L7: 0.46133315 | M7: Skipped (JSD=0.076) | N7: 0.075834592 | O7: 0
A8: 3 | B8: 3000 | C8: New credit | D8: Fidelity | E8: Real-World | F8: N/A | G8: 0.1 | H8: 0.4 | I8: 0.05 | J8: 0.78787879 | K8: 0.81384615 | L8: 0.64449282 | M8: Optimized (JSD=1.000) | N8: 1 | O8: 1
A9: 3 | B9: 3000 | C9: New credit | D9: Parsimony | E9: Real-World | F9: N/A | G9: 0.54444444 | H9: 0.4 | I9: 0.05 | J9: 0.72727273 | K9: 0.84 | L9: 0.67339138 | M9: Optimized (JSD=1.000) | N9: 1 | O9: 1
A10: 3 | B10: 3000 | C10: New credit | D10: Strictness | E10: Real-World | F10: N/A | G10: 0.9 | H10: 0.4 | I10: 0.05 | J10: 0.39393939 | K10: 0.91461538 | L10: 0.47509674 | M10: Optimized (JSD=1.000) | N10: 1 | O10: 1
A11: 4 | B11: 4000 | C11: New credit | D11: Fidelity | E11: Real-World | F11: N/A | G11: 0.1 | H11: 0.4 | I11: 0.05 | J11: 0.74358974 | K11: 0.7962069 | L11: 0.75632295 | M11: Optimized (JSD=1.000) | N11: 1 | O11: 1
A12: 4 | B12: 4000 | C12: New credit | D12: Parsimony | E12: Real-World | F12: N/A | G12: 0.1 | H12: 0.4 | I12: 0.05 | J12: 0.74358974 | K12: 0.7962069 | L12: 0.75632295 | M12: Optimized (JSD=1.000) | N12: 1 | O12: 1
A13: 4 | B13: 4000 | C13: New credit | D13: Strictness | E13: Real-World | F13: N/A | G13: 0.9 | H13: 0.4 | I13: 0.05 | J13: 0.33333333 | K13: 0.91384615 | L13: 0.49388268 | M13: Optimized (JSD=1.000) | N13: 1 | O13: 1
... A1426: 475 | B1426: 475000 | C1426: New credit | D1426: Strictness | E1426: Real-World | F1426: N/A | G1426: 0.9 | H1426: 0.8 | I1426: 0.05 | J1426: 0.390625 | K1426: 0.886 | L1426: 0.92298222 | M1426: Optimized (JSD=1.000) | N1426: 1 | O1426: 1
